<sdf version='1.11'>
  <model name='manipulator'>
    <link name='base_plate'>
      <inertial>
        <pose>0.00070370370370370367 0 -0.017351851851851851 0 0 0</pose>
        <mass>0.13500000000000001</mass>
        <inertia>
          <ixx>5.6418495370037038e-05</ixx>
          <ixy>0</ixy>
          <ixz>3.149074074074075e-06</ixz>
          <iyy>6.6885393518185195e-05</iyy>
          <iyz>0</iyz>
          <izz>3.9168148148148149e-05</izz>
        </inertia>
      </inertial>
      <collision name='base_plate_collision'>
        <pose>0 0 0 0 0 0</pose>
        <geometry>
          <cylinder>
            <length>0.0050000000000000001</length>
            <radius>0.029999999999999999</radius>
          </cylinder>
        </geometry>
        <surface>
          <contact>
            <ode>
              <kp>1000000</kp>
              <kd>100</kd>
              <min_depth>0.001</min_depth>
            </ode>
          </contact>
          <friction>
            <ode>
              <mu>0.80000000000000004</mu>
              <mu2>0.80000000000000004</mu2>
            </ode>
          </friction>
        </surface>
      </collision>
      <collision name='base_plate_fixed_joint_lump__arm_motor_1_collision_1'>
        <pose>0 0 -0.024500000000000001 0 0 0</pose>
        <geometry>
          <box>
            <size>0.044999999999999998 0.021999999999999999 0.043999999999999997</size>
          </box>
        </geometry>
      </collision>
      <collision name='base_plate_fixed_joint_lump__razor_connector_collision_2'>
        <pose>0.0094999999999999998 0 -0.050500000000000003 0 0 0</pose>
        <geometry>
          <cylinder>
            <length>0.0080000000000000002</length>
            <radius>0.0054999999999999997</radius>
          </cylinder>
        </geometry>
        <surface>
          <contact>
            <ode>
              <kp>1000000</kp>
              <kd>100</kd>
            </ode>
          </contact>
          <friction>
            <ode>
              <mu>0.80000000000000004</mu>
              <mu2>0.80000000000000004</mu2>
            </ode>
          </friction>
        </surface>
      </collision>
      <visual name='base_plate_visual'>
        <pose>0 0 0 0 0 0</pose>
        <geometry>
          <cylinder>
            <length>0.0050000000000000001</length>
            <radius>0.029999999999999999</radius>
          </cylinder>
        </geometry>
      </visual>
      <visual name='base_plate_fixed_joint_lump__arm_motor_1_visual_1'>
        <pose>0 0 -0.024500000000000001 0 0 0</pose>
        <geometry>
          <box>
            <size>0.044999999999999998 0.021999999999999999 0.043999999999999997</size>
          </box>
        </geometry>
      </visual>
      <visual name='base_plate_fixed_joint_lump__razor_connector_visual_2'>
        <pose>0.0094999999999999998 0 -0.050500000000000003 0 0 0</pose>
        <geometry>
          <cylinder>
            <length>0.0080000000000000002</length>
            <radius>0.0054999999999999997</radius>
          </cylinder>
        </geometry>
      </visual>
    </link>
    <joint name='joint_1' type='revolute'>
      <pose relative_to='base_plate'>0.0094999999999999998 -0.01 -0.066500000000000004 0 0 0</pose>
      <parent>base_plate</parent>
      <child>arm_motor_2</child>
      <axis>
        <xyz>0 0 1</xyz>
        <limit>
          <lower>-3.1400000000000001</lower>
          <upper>3.1400000000000001</upper>
          <effort>2</effort>
          <velocity>5</velocity>
        </limit>
        <dynamics>
          <damping>0.10000000000000001</damping>
          <friction>0.10000000000000001</friction>
          <spring_reference>0</spring_reference>
          <spring_stiffness>0</spring_stiffness>
        </dynamics>
      </axis>
      <physics>
        <ode>
          <limit>
            <cfm>0</cfm>
            <erp>0.20000000000000001</erp>
          </limit>
        </ode>
      </physics>
      <initial_position>0.0</initial_position>
    </joint>
    <link name='arm_motor_2'>
      <pose relative_to='joint_1'>0 0 0 0 0 0</pose>
      <inertial>
        <pose>0 0 0 0 0 0</pose>
        <mass>0.082000000000000003</mass>
        <inertia>
          <ixx>2.1019333299999999e-05</ixx>
          <ixy>0</ixy>
          <ixz>0</ixz>
          <iyy>2.3130833300000001e-05</iyy>
          <iyz>0</iyz>
          <izz>3.6278166700000003e-05</izz>
        </inertia>
      </inertial>
      <collision name='arm_motor_2_collision'>
        <pose>0 0 0 0 0 0</pose>
        <geometry>
          <box>
            <size>0.052999999999999999 0.050000000000000003 0.024</size>
          </box>
        </geometry>
      </collision>
      <visual name='arm_motor_2_visual'>
        <pose>0 0 0 0 0 0</pose>
        <geometry>
          <box>
            <size>0.052999999999999999 0.050000000000000003 0.024</size>
          </box>
        </geometry>
      </visual>
    </link>
    <joint name='joint_2' type='revolute'>
      <pose relative_to='arm_motor_2'>0 0.012500000000000001 0 0 0 0</pose>
      <parent>arm_motor_2</parent>
      <child>h_arm</child>
      <axis>
        <xyz>1 0 0</xyz>
        <limit>
          <lower>-1.5700000000000001</lower>
          <upper>1.5700000000000001</upper>
          <effort>2</effort>
          <velocity>3</velocity>
        </limit>
        <dynamics>
          <damping>0.10000000000000001</damping>
          <friction>0.10000000000000001</friction>
          <spring_reference>0</spring_reference>
          <spring_stiffness>0</spring_stiffness>
        </dynamics>
      </axis>
      <physics>
        <ode>
          <limit>
            <cfm>0</cfm>
            <erp>0.20000000000000001</erp>
          </limit>
        </ode>
      </physics>
      <initial_position>0.0</initial_position>
    </joint>
    <link name='h_arm'>
      <pose relative_to='joint_2'>0 0 0 0 0 0</pose>
      <inertial>
        <pose>0 0 -0.051999999999999998 0 0 0</pose>
        <mass>0.053999999999999999</mass>
        <inertia>
          <ixx>0.0001980045</ixx>
          <ixy>0</ixy>
          <ixz>0</ixz>
          <iyy>0.0002266425</iyy>
          <iyz>0</iyz>
          <izz>3.4263e-05</izz>
        </inertia>
      </inertial>
      <collision name='h_arm_collision'>
        <pose>0 0 -0.051999999999999998 0 0 0</pose>
        <geometry>
          <box>
            <size>0.057000000000000002 0.025000000000000001 0.128</size>
          </box>
        </geometry>
        <surface>
          <contact>
            <ode>
              <kp>1000000</kp>
              <kd>100</kd>
            </ode>
          </contact>
          <friction>
            <ode>
              <mu>0.80000000000000004</mu>
              <mu2>0.80000000000000004</mu2>
            </ode>
          </friction>
        </surface>
      </collision>
      <visual name='h_arm_visual'>
        <pose>0 0 -0.051999999999999998 0 0 0</pose>
        <geometry>
          <box>
            <size>0.057000000000000002 0.025000000000000001 0.128</size>
          </box>
        </geometry>
      </visual>
    </link>
    <joint name='joint_3' type='revolute'>
      <pose relative_to='h_arm'>0 0 -0.106 0 0 0</pose>
      <parent>h_arm</parent>
      <child>arm_motor_3</child>
      <axis>
        <xyz>1 0 0</xyz>
        <limit>
          <lower>-1.5700000000000001</lower>
          <upper>1.5700000000000001</upper>
          <effort>2</effort>
          <velocity>3</velocity>
        </limit>
        <dynamics>
          <damping>0.10000000000000001</damping>
          <friction>0.10000000000000001</friction>
          <spring_reference>0</spring_reference>
          <spring_stiffness>0</spring_stiffness>
        </dynamics>
      </axis>
      <physics>
        <ode>
          <limit>
            <cfm>0</cfm>
            <erp>0.20000000000000001</erp>
          </limit>
        </ode>
      </physics>
      <initial_position>0.0</initial_position>
    </joint>
    <link name='arm_motor_3'>
      <pose relative_to='joint_3'>0 0 0 0 0 0</pose>
      <inertial>
        <pose>0.007458333333333335 -0.0073333333333333332 -0.067833333333333329 0 0 0</pose>
        <mass>0.17999999999999999</mass>
        <inertia>
          <ixx>0.00058716999993999985</ixx>
          <ixy>2.3815000000000002e-05</ixy>
          <ixz>8.1126249999999999e-05</ixz>
          <iyy>0.0006087246874999999</iyy>
          <iyz>-7.8099999999999987e-05</iyz>
          <izz>9.3361354169999998e-05</izz>
        </inertia>
      </inertial>
      <collision name='arm_motor_3_collision'>
        <pose>0 0 -0.014999999999999999 0 0 0</pose>
        <geometry>
          <box>
            <size>0.052999999999999999 0.025000000000000001 0.059999999999999998</size>
          </box>
        </geometry>
      </collision>
      <collision name='arm_motor_3_fixed_joint_lump__rod_collision_1'>
        <pose>-0.0015 0 -0.072499999999999995 0 0 0</pose>
        <geometry>
          <cylinder>
            <length>0.055</length>
            <radius>0.0060000000000000001</radius>
          </cylinder>
        </geometry>
        <surface>
          <contact>
            <ode>
              <kp>1000000</kp>
              <kd>100</kd>
            </ode>
          </contact>
          <friction>
            <ode>
              <mu>0.80000000000000004</mu>
              <mu2>0.80000000000000004</mu2>
            </ode>
          </friction>
        </surface>
      </collision>
      <collision name='arm_motor_3_fixed_joint_lump__gripper_base_collision_2'>
        <pose>-0.0015 0 -0.125 0 0 0</pose>
        <geometry>
          <box>
            <size>0.040000000000000001 0.0030000000000000001 0.050000000000000003</size>
          </box>
        </geometry>
        <surface>
          <contact>
            <ode>
              <kp>1000000</kp>
              <kd>100</kd>
            </ode>
          </contact>
          <friction>
            <ode>
              <mu>0.80000000000000004</mu>
              <mu2>0.80000000000000004</mu2>
            </ode>
          </friction>
        </surface>
      </collision>
      <collision name='arm_motor_3_fixed_joint_lump__arm_motor_4_collision_3'>
        <pose>0.025499999999999998 -0.024 -0.127 0 0 0</pose>
        <geometry>
          <box>
            <size>0.043999999999999997 0.044999999999999998 0.02</size>
          </box>
        </geometry>
      </collision>
      <visual name='arm_motor_3_visual'>
        <pose>0 0 -0.014999999999999999 0 0 0</pose>
        <geometry>
          <box>
            <size>0.052999999999999999 0.025000000000000001 0.059999999999999998</size>
          </box>
        </geometry>
      </visual>
      <visual name='arm_motor_3_fixed_joint_lump__rod_visual_1'>
        <pose>-0.0015 0 -0.072499999999999995 0 0 0</pose>
        <geometry>
          <cylinder>
            <length>0.055</length>
            <radius>0.0060000000000000001</radius>
          </cylinder>
        </geometry>
      </visual>
      <visual name='arm_motor_3_fixed_joint_lump__gripper_base_visual_2'>
        <pose>-0.0015 0 -0.125 0 0 0</pose>
        <geometry>
          <box>
            <size>0.040000000000000001 0.0030000000000000001 0.050000000000000003</size>
          </box>
        </geometry>
      </visual>
      <visual name='arm_motor_3_fixed_joint_lump__arm_motor_4_visual_3'>
        <pose>0.025499999999999998 -0.024 -0.127 0 0 0</pose>
        <geometry>
          <box>
            <size>0.043999999999999997 0.044999999999999998 0.02</size>
          </box>
        </geometry>
      </visual>
    </link>
    <joint name='joint_4' type='revolute'>
      <pose relative_to='arm_motor_3'>-0.0115 0.0030000000000000001 -0.125 0 0 0</pose>
      <parent>arm_motor_3</parent>
      <child>gripper_L</child>
      <axis>
        <xyz>0 1 0</xyz>
        <limit>
          <lower>-0.001</lower>
          <upper>1.2</upper>
          <effort>1</effort>
          <velocity>2</velocity>
        </limit>
        <dynamics>
          <damping>0.050000000000000003</damping>
          <friction>0.050000000000000003</friction>
          <spring_reference>0</spring_reference>
          <spring_stiffness>0</spring_stiffness>
        </dynamics>
      </axis>
      <physics>
        <ode>
          <limit>
            <cfm>0</cfm>
            <erp>0.20000000000000001</erp>
          </limit>
        </ode>
      </physics>
      <initial_position>0.01</initial_position>
    </joint>
    <link name='gripper_L'>
      <pose relative_to='joint_4'>0 0 0 0 0 0</pose>
      <inertial>
        <pose>0 0 -0.021999999999999999 0 0 0</pose>
        <mass>0.02</mass>
        <inertia>
          <ixx>1.5695000000000001e-05</ixx>
          <ixy>0</ixy>
          <ixz>0</ixz>
          <iyy>1.58466667e-05</iyy>
          <iyz>0</iyz>
          <izz>1.8166666699999999e-07</izz>
        </inertia>
      </inertial>
      <collision name='gripper_L_collision'>
        <pose>0 0 -0.021999999999999999 0 0 0</pose>
        <geometry>
          <box>
            <size>0.01 0.0030000000000000001 0.059999999999999998</size>
          </box>
        </geometry>
        <surface>
          <contact>
            <ode>
              <kp>1000000</kp>
              <kd>100</kd>
            </ode>
          </contact>
          <friction>
            <ode>
              <mu>1</mu>
              <mu2>1</mu2>
            </ode>
          </friction>
        </surface>
      </collision>
      <visual name='gripper_L_visual'>
        <pose>-0.0089999999999999993 -0.002 -0.074999999999999997 -1.570796326794897 -1.5707963267948966 0</pose>
        <geometry>
          <mesh>
            <scale>0.0015 0.0015 0.0015</scale>
            <uri>model://manipulator_description/meshes/left_finger.STL</uri>
          </mesh>
        </geometry>
        <material>
          <diffuse>0.125 0.125 0.125 1</diffuse>
          <ambient>0.125 0.125 0.125 1</ambient>
        </material>
      </visual>
    </link>
    <joint name='joint_5' type='revolute'>
      <pose relative_to='arm_motor_3'>0.0085000000000000006 0.0030000000000000001 -0.125 0 0 0</pose>
      <parent>arm_motor_3</parent>
      <child>gripper_R</child>
      <axis>
        <xyz>0 1 0</xyz>
        <mimic joint='joint_4'>
          <multiplier>-1</multiplier>
          <offset>0</offset>
          <reference>0</reference>
        </mimic>
        <limit>
          <lower>-1.2</lower>
          <upper>0.001</upper>
          <effort>1</effort>
          <velocity>2</velocity>
        </limit>
        <dynamics>
          <damping>0.050000000000000003</damping>
          <friction>0.050000000000000003</friction>
          <spring_reference>0</spring_reference>
          <spring_stiffness>0</spring_stiffness>
        </dynamics>
      </axis>
      <physics>
        <ode>
          <limit>
            <cfm>0</cfm>
            <erp>0.20000000000000001</erp>
          </limit>
        </ode>
      </physics>
      <initial_position>-0.01</initial_position>
    </joint>
    <link name='gripper_R'>
      <pose relative_to='joint_5'>0 0 0 0 0 0</pose>
      <inertial>
        <pose>0 0 -0.021999999999999999 0 0 0</pose>
        <mass>0.02</mass>
        <inertia>
          <ixx>1.5695000000000001e-05</ixx>
          <ixy>0</ixy>
          <ixz>0</ixz>
          <iyy>1.58466667e-05</iyy>
          <iyz>0</iyz>
          <izz>1.8166666699999999e-07</izz>
        </inertia>
      </inertial>
      <collision name='gripper_R_collision'>
        <pose>0 0 -0.021999999999999999 0 0 0</pose>
        <geometry>
          <box>
            <size>0.01 0.0030000000000000001 0.059999999999999998</size>
          </box>
        </geometry>
        <surface>
          <contact>
            <ode>
              <kp>1000000</kp>
              <kd>100</kd>
            </ode>
          </contact>
          <friction>
            <ode>
              <mu>1</mu>
              <mu2>1</mu2>
            </ode>
          </friction>
        </surface>
      </collision>
      <visual name='gripper_R_visual'>
        <pose>-0.010999999999999999 -0.002 -0.074999999999999997 -1.570796326794897 -1.5707963267948966 0</pose>
        <geometry>
          <mesh>
            <scale>0.0015 0.0015 0.0015</scale>
            <uri>model://manipulator_description/meshes/right_finger.STL</uri>
          </mesh>
        </geometry>
        <material>
          <diffuse>0.125 0.125 0.125 1</diffuse>
          <ambient>0.125 0.125 0.125 1</ambient>
        </material>
      </visual>
    </link>
    <plugin name='gz_ros2_control::GazeboSimROS2ControlPlugin' filename='gz_ros2_control-system'>
      <parameters>/home/lahiru/newlocalrepo/rl-aerial-manipulator/Manipulator/install/manipulator_controller/share/manipulator_controller/config/manipulator_controllers.yaml</parameters>
      <controller_manager_name>controller_manager</controller_manager_name>
    </plugin>
    <frame name='joint_motor1_to_connector' attached_to='arm_motor_1'>
      <pose>0.0094999999999999998 0 -0.025999999999999999 0 0 0</pose>
    </frame>
    <frame name='razor_connector' attached_to='joint_motor1_to_connector'>
      <pose>0 0 0 0 0 0</pose>
    </frame>
    <frame name='joint_gripperbase_to_motor4' attached_to='gripper_base'>
      <pose>0.027 -0.024 -0.002 0 0 0</pose>
    </frame>
    <frame name='arm_motor_4' attached_to='joint_gripperbase_to_motor4'>
      <pose>0 0 0 0 0 0</pose>
    </frame>
    <frame name='joint_rod_to_gripper_base' attached_to='rod'>
      <pose>0 0 -0.052499999999999998 0 0 0</pose>
    </frame>
    <frame name='gripper_base' attached_to='joint_rod_to_gripper_base'>
      <pose>0 0 0 0 0 0</pose>
    </frame>
    <frame name='joint_motor3_to_rod' attached_to='arm_motor_3'>
      <pose>-0.0015 0 -0.072499999999999995 0 0 0</pose>
    </frame>
    <frame name='rod' attached_to='joint_motor3_to_rod'>
      <pose>0 0 0 0 0 0</pose>
    </frame>
    <frame name='joint_motor_1' attached_to='base_plate'>
      <pose>0 0 -0.024500000000000001 0 0 0</pose>
    </frame>
    <frame name='arm_motor_1' attached_to='joint_motor_1'>
      <pose>0 0 0 0 0 0</pose>
    </frame>
  </model>
</sdf>
