<?xml version="1.0" ?>
<robot name="custom_hexa">

  <!-- ========================= DUMMY ROOT LINK (Required by KDL/RViz) ========================= -->
  <link name="world"/>
  
  <joint name="world_to_base" type="fixed">
    <parent link="world"/>
    <child link="base_link"/>
    <origin xyz="0 0 0.0015" rpy="0 0 0"/>
  </joint>

  <!-- ========================= BASE_LINK ========================= -->
  <link name="base_link">
    <inertial>
      <origin xyz="0 0 0.0425" rpy="0 0 0"/>
      <mass value="1.9949"/>
      <inertia ixx="0.0105521906" ixy="0" ixz="0" 
               iyy="0.0105521906" iyz="0" izz="0.0187021875"/>
    </inertial>
    <visual>
      <origin xyz="0 0 0" rpy="0 0 0"/>
      <geometry>
        <mesh filename="file:///home/lahiru/newlocalrepo/rl-aerial-manipulator/hexacopter_description/custom_hexa/meshes/Lower_plate_CG.STL" 
              scale="0.0014 0.0014 0.0014"/>
      </geometry>
      <material name="base_material">
        <color rgba="0.9 0.9 0.9 1"/>
      </material>
    </visual>
    <collision>
      <origin xyz="0 0 0" rpy="0 0 0"/>
      <geometry>
        <cylinder radius="0.15" length="0.003"/>
      </geometry>
    </collision>
  </link>

  <!-- ========================= TOP PLATE ========================= -->
  <link name="Top_plate_link">
    <inertial>
      <origin xyz="0 0 0" rpy="0 0 0"/>
      <mass value="0.001"/>
      <inertia ixx="4.76e-06" ixy="0" ixz="0" 
               iyy="4.76e-06" iyz="0" izz="9.38e-06"/>
    </inertial>
    <visual>
      <origin xyz="0 0 0" rpy="0 0 0"/>
      <geometry>
        <mesh filename="file:///home/lahiru/newlocalrepo/rl-aerial-manipulator/hexacopter_description/custom_hexa/meshes/Top_plate_CG.STL" 
              scale="0.0014 0.0014 0.0014"/>
      </geometry>
      <material name="top_plate_material">
        <color rgba="0.9 0.9 0.9 1"/>
      </material>
    </visual>
    <collision>
      <origin xyz="0 0 0" rpy="0 0 0"/>
      <geometry>
        <cylinder radius="0.12" length="0.003"/>
      </geometry>
    </collision>
  </link>

  <joint name="Lower_Top_joint" type="fixed">
    <parent link="base_link"/>
    <child link="Top_plate_link"/>
    <origin xyz="0 0 0.085" rpy="0 0 0"/>
  </joint>

  <!-- ========================= IMU LINK ========================= -->
  <link name="imu_link">
    <inertial>
      <origin xyz="0 0 0" rpy="0 0 0"/>
      <mass value="0.0001"/>
      <inertia ixx="1e-09" ixy="0" ixz="0" 
               iyy="1e-09" iyz="0" izz="1e-09"/>
    </inertial>
    <visual>
      <origin xyz="0 0 0" rpy="0 0 0"/>
      <geometry>
        <box size="0.01 0.02 0.02"/>
      </geometry>
      <material name="imu_material">
        <color rgba="0.2 0.2 0.2 1"/>
      </material>
    </visual>
    <collision>
      <origin xyz="0 0 0" rpy="0 0 0"/>
      <geometry>
        <box size="0.01 0.02 0.02"/>
      </geometry>
    </collision>
  </link>

  <joint name="imu_joint" type="fixed">
    <parent link="Top_plate_link"/>
    <child link="imu_link"/>
    <origin xyz="0 0 0" rpy="0 0 3.1415927"/>
  </joint>

  <!-- ========================= ARM 1 ========================= -->
  <link name="Arm1_link">
    <inertial>
      <origin xyz="0.079425 0 -0.005" rpy="0 0 0"/>
      <mass value="0.0126"/>
      <inertia ixx="3.44e-07" ixy="0" ixz="0" 
               iyy="2.66e-05" iyz="0" izz="2.66e-05"/>
    </inertial>
    <visual>
      <origin xyz="0.079425 0 -0.005" rpy="0 0 0"/>
      <geometry>
        <box size="0.15885 0.01 0.01"/>
      </geometry>
      <material name="arm_material">
        <color rgba="0.8 0.0 0.0 1"/>
      </material>
    </visual>
    <collision>
      <origin xyz="0.079425 0 -0.005" rpy="0 0 0"/>
      <geometry>
        <box size="0.15885 0.01 0.01"/>
      </geometry>
    </collision>
  </link>

  <joint name="Lower_Arm1_joint" type="fixed">
    <parent link="base_link"/>
    <child link="Arm1_link"/>
    <origin xyz="0 0.15 0.0535" rpy="0 0 1.57079632679"/>
  </joint>

  <!-- ========================= ARM 2 ========================= -->
  <link name="Arm2_link">
    <inertial>
      <origin xyz="0.079425 0 -0.005" rpy="0 0 0"/>
      <mass value="0.0126"/>
      <inertia ixx="3.44e-07" ixy="0" ixz="0" 
               iyy="2.66e-05" iyz="0" izz="2.66e-05"/>
    </inertial>
    <visual>
      <origin xyz="0.079425 0 -0.005" rpy="0 0 0"/>
      <geometry>
        <box size="0.15885 0.01 0.01"/>
      </geometry>
      <material name="arm_material"/>
    </visual>
    <collision>
      <origin xyz="0.079425 0 -0.005" rpy="0 0 0"/>
      <geometry>
        <box size="0.15885 0.01 0.01"/>
      </geometry>
    </collision>
  </link>

  <joint name="Lower_Arm2_joint" type="fixed">
    <parent link="base_link"/>
    <child link="Arm2_link"/>
    <origin xyz="0.129903810567 0.075 0.0535" rpy="0 0 0.523598775598"/>
  </joint>

  <!-- ========================= ARM 3 ========================= -->
  <link name="Arm3_link">
    <inertial>
      <origin xyz="0.079425 0 -0.005" rpy="0 0 0"/>
      <mass value="0.0126"/>
      <inertia ixx="3.44e-07" ixy="0" ixz="0" 
               iyy="2.66e-05" iyz="0" izz="2.66e-05"/>
    </inertial>
    <visual>
      <origin xyz="0.079425 0 -0.005" rpy="0 0 0"/>
      <geometry>
        <box size="0.15885 0.01 0.01"/>
      </geometry>
      <material name="arm_material"/>
    </visual>
    <collision>
      <origin xyz="0.079425 0 -0.005" rpy="0 0 0"/>
      <geometry>
        <box size="0.15885 0.01 0.01"/>
      </geometry>
    </collision>
  </link>

  <joint name="Lower_Arm3_joint" type="fixed">
    <parent link="base_link"/>
    <child link="Arm3_link"/>
    <origin xyz="0.129903810567 -0.075 0.0535" rpy="0 0 -0.523598775598"/>
  </joint>

  <!-- ========================= ARM 4 ========================= -->
  <link name="Arm4_link">
    <inertial>
      <origin xyz="0.079425 0 -0.005" rpy="0 0 0"/>
      <mass value="0.0126"/>
      <inertia ixx="3.44e-07" ixy="0" ixz="0" 
               iyy="2.66e-05" iyz="0" izz="2.66e-05"/>
    </inertial>
    <visual>
      <origin xyz="0.079425 0 -0.005" rpy="0 0 0"/>
      <geometry>
        <box size="0.15885 0.01 0.01"/>
      </geometry>
      <material name="arm_material"/>
    </visual>
    <collision>
      <origin xyz="0.079425 0 -0.005" rpy="0 0 0"/>
      <geometry>
        <box size="0.15885 0.01 0.01"/>
      </geometry>
    </collision>
  </link>

  <joint name="Lower_Arm4_joint" type="fixed">
    <parent link="base_link"/>
    <child link="Arm4_link"/>
    <origin xyz="0 -0.15 0.0535" rpy="0 0 -1.57079632679"/>
  </joint>

  <!-- ========================= ARM 5 ========================= -->
  <link name="Arm5_link">
    <inertial>
      <origin xyz="0.079425 0 -0.005" rpy="0 0 0"/>
      <mass value="0.0126"/>
      <inertia ixx="3.44e-07" ixy="0" ixz="0" 
               iyy="2.66e-05" iyz="0" izz="2.66e-05"/>
    </inertial>
    <visual>
      <origin xyz="0.079425 0 -0.005" rpy="0 0 0"/>
      <geometry>
        <box size="0.15885 0.01 0.01"/>
      </geometry>
      <material name="arm_material"/>
    </visual>
    <collision>
      <origin xyz="0.079425 0 -0.005" rpy="0 0 0"/>
      <geometry>
        <box size="0.15885 0.01 0.01"/>
      </geometry>
    </collision>
  </link>

  <joint name="Lower_Arm5_joint" type="fixed">
    <parent link="base_link"/>
    <child link="Arm5_link"/>
    <origin xyz="-0.129903810567 -0.075 0.0535" rpy="0 0 3.66519142919"/>
  </joint>

  <!-- ========================= ARM 6 ========================= -->
  <link name="Arm6_link">
    <inertial>
      <origin xyz="0.079425 0 -0.005" rpy="0 0 0"/>
      <mass value="0.0126"/>
      <inertia ixx="3.44e-07" ixy="0" ixz="0" 
               iyy="2.66e-05" iyz="0" izz="2.66e-05"/>
    </inertial>
    <visual>
      <origin xyz="0.079425 0 -0.005" rpy="0 0 0"/>
      <geometry>
        <box size="0.15885 0.01 0.01"/>
      </geometry>
      <material name="arm_material"/>
    </visual>
    <collision>
      <origin xyz="0.079425 0 -0.005" rpy="0 0 0"/>
      <geometry>
        <box size="0.15885 0.01 0.01"/>
      </geometry>
    </collision>
  </link>

  <joint name="Lower_Arm6_joint" type="fixed">
    <parent link="base_link"/>
    <child link="Arm6_link"/>
    <origin xyz="-0.129903810567 0.075 0.0535" rpy="0 0 2.61799387799"/>
  </joint>

  <!-- ========================= ROTOR 0 ========================= -->
  <link name="rotor_0">
    <inertial>
      <origin xyz="0 0 0" rpy="0 0 0"/>
      <mass value="0.008"/>
      <inertia ixx="5.205e-05" ixy="0" ixz="0" 
               iyy="2.667e-07" iyz="0" izz="5.230e-05"/>
    </inertial>
    <visual>
      <origin xyz="0 0 0" rpy="0 0 0"/>
      <geometry>
        <mesh filename="file:///home/lahiru/newlocalrepo/rl-aerial-manipulator/hexacopter_description/custom_hexa/meshes/prop_cw_CG.stl" 
              scale="0.001 0.001 0.001"/>
      </geometry>
      <material name="rotor_material">
        <color rgba="1.0 1.0 0.2 1"/>
      </material>
    </visual>
    <collision>
      <origin xyz="0 0 0" rpy="0 0 0"/>
      <geometry>
        <cylinder radius="0.128" length="0.005"/>
      </geometry>
    </collision>
  </link>

  <joint name="rotor_0_joint" type="continuous">
    <parent link="base_link"/>
    <child link="rotor_0"/>
    <origin xyz="-0.255691 0.1475 0.0915" rpy="0 0 2.09439510239"/>
    <axis xyz="0 0 1"/>
    <limit effort="100000" velocity="4000"/>
    <dynamics damping="0.005"/>
  </joint>

  <!-- ========================= MOTOR 0 ========================= -->
  <link name="motor_0">
    <inertial>
      <origin xyz="0 0 0" rpy="0 0 0"/>
      <mass value="0.072"/>
      <inertia ixx="8.928e-06" ixy="0" ixz="0" 
               iyy="8.928e-06" iyz="0" izz="7.056e-06"/>
    </inertial>
    <visual>
      <origin xyz="0 0 0" rpy="0 0 0"/>
      <geometry>
        <cylinder radius="0.014" length="0.032"/>
      </geometry>
      <material name="motor_material">
        <color rgba="0.2 0.2 0.2 1"/>
      </material>
    </visual>
    <collision>
      <origin xyz="0 0 0" rpy="0 0 0"/>
      <geometry>
        <cylinder radius="0.014" length="0.032"/>
      </geometry>
    </collision>
  </link>

  <joint name="base_motor_0" type="fixed">
    <parent link="base_link"/>
    <child link="motor_0"/>
    <origin xyz="-0.255691 0.1475 0.0695" rpy="0 0 2.09439510239"/>
  </joint>

  <!-- ========================= ROTOR 1 ========================= -->
  <link name="rotor_1">
    <inertial>
      <origin xyz="0 0 0" rpy="0 0 0"/>
      <mass value="0.008"/>
      <inertia ixx="5.205e-05" ixy="0" ixz="0" 
               iyy="2.667e-07" iyz="0" izz="5.230e-05"/>
    </inertial>
    <visual>
      <origin xyz="0 0 0" rpy="0 0 0"/>
      <geometry>
        <mesh filename="file:///home/lahiru/newlocalrepo/rl-aerial-manipulator/hexacopter_description/custom_hexa/meshes/prop_ccw_CG.stl" 
              scale="0.001 0.001 0.001"/>
      </geometry>
      <material name="rotor_material"/>
    </visual>
    <collision>
      <origin xyz="0 0 0" rpy="0 0 0"/>
      <geometry>
        <cylinder radius="0.128" length="0.005"/>
      </geometry>
    </collision>
  </link>

  <joint name="rotor_1_joint" type="continuous">
    <parent link="base_link"/>
    <child link="rotor_1"/>
    <origin xyz="0.255691 -0.1475 0.0915" rpy="0 0 -2.09439510239"/>
    <axis xyz="0 0 1"/>
    <limit effort="100000" velocity="4000"/>
    <dynamics damping="0.005"/>
  </joint>

  <!-- ========================= MOTOR 1 ========================= -->
  <link name="motor_1">
    <inertial>
      <origin xyz="0 0 0" rpy="0 0 0"/>
      <mass value="0.072"/>
      <inertia ixx="8.928e-06" ixy="0" ixz="0" 
               iyy="8.928e-06" iyz="0" izz="7.056e-06"/>
    </inertial>
    <visual>
      <origin xyz="0 0 0" rpy="0 0 0"/>
      <geometry>
        <cylinder radius="0.014" length="0.032"/>
      </geometry>
      <material name="motor_material"/>
    </visual>
    <collision>
      <origin xyz="0 0 0" rpy="0 0 0"/>
      <geometry>
        <cylinder radius="0.014" length="0.032"/>
      </geometry>
    </collision>
  </link>

  <joint name="base_motor_1" type="fixed">
    <parent link="base_link"/>
    <child link="motor_1"/>
    <origin xyz="0.255691 -0.1475 0.0695" rpy="0 0 -2.09439510239"/>
  </joint>

  <!-- ========================= ROTOR 2 ========================= -->
  <link name="rotor_2">
    <inertial>
      <origin xyz="0 0 0" rpy="0 0 0"/>
      <mass value="0.008"/>
      <inertia ixx="5.205e-05" ixy="0" ixz="0" 
               iyy="2.667e-07" iyz="0" izz="5.230e-05"/>
    </inertial>
    <visual>
      <origin xyz="0 0 0" rpy="0 0 0"/>
      <geometry>
        <mesh filename="file:///home/lahiru/newlocalrepo/rl-aerial-manipulator/hexacopter_description/custom_hexa/meshes/prop_ccw_CG.stl" 
              scale="0.001 0.001 0.001"/>
      </geometry>
      <material name="rotor_material"/>
    </visual>
    <collision>
      <origin xyz="0 0 0" rpy="0 0 0"/>
      <geometry>
        <cylinder radius="0.128" length="0.005"/>
      </geometry>
    </collision>
  </link>

  <joint name="rotor_2_joint" type="continuous">
    <parent link="base_link"/>
    <child link="rotor_2"/>
    <origin xyz="-0.255691 -0.1475 0.0915" rpy="0 0 2.09439510239"/>
    <axis xyz="0 0 1"/>
    <limit effort="100000" velocity="4000"/>
    <dynamics damping="0.005"/>
  </joint>

  <!-- ========================= MOTOR 2 ========================= -->
  <link name="motor_2">
    <inertial>
      <origin xyz="0 0 0" rpy="0 0 0"/>
      <mass value="0.072"/>
      <inertia ixx="8.928e-06" ixy="0" ixz="0" 
               iyy="8.928e-06" iyz="0" izz="7.056e-06"/>
    </inertial>
    <visual>
      <origin xyz="0 0 0" rpy="0 0 0"/>
      <geometry>
        <cylinder radius="0.014" length="0.032"/>
      </geometry>
      <material name="motor_material"/>
    </visual>
    <collision>
      <origin xyz="0 0 0" rpy="0 0 0"/>
      <geometry>
        <cylinder radius="0.014" length="0.032"/>
      </geometry>
    </collision>
  </link>

  <joint name="base_motor_2" type="fixed">
    <parent link="base_link"/>
    <child link="motor_2"/>
    <origin xyz="-0.255691 -0.1475 0.0695" rpy="0 0 2.09439510239"/>
  </joint>

  <!-- ========================= ROTOR 3 ========================= -->
  <link name="rotor_3">
    <inertial>
      <origin xyz="0 0 0" rpy="0 0 0"/>
      <mass value="0.008"/>
      <inertia ixx="5.205e-05" ixy="0" ixz="0" 
               iyy="2.667e-07" iyz="0" izz="5.230e-05"/>
    </inertial>
    <visual>
      <origin xyz="0 0 0" rpy="0 0 0"/>
      <geometry>
        <mesh filename="file:///home/lahiru/newlocalrepo/rl-aerial-manipulator/hexacopter_description/custom_hexa/meshes/prop_cw_CG.stl" 
              scale="0.001 0.001 0.001"/>
      </geometry>
      <material name="rotor_material"/>
    </visual>
    <collision>
      <origin xyz="0 0 0" rpy="0 0 0"/>
      <geometry>
        <cylinder radius="0.128" length="0.005"/>
      </geometry>
    </collision>
  </link>

  <joint name="rotor_3_joint" type="continuous">
    <parent link="base_link"/>
    <child link="rotor_3"/>
    <origin xyz="0.255691 0.1475 0.0915" rpy="0 0 0"/>
    <axis xyz="0 0 1"/>
    <limit effort="100000" velocity="4000"/>
    <dynamics damping="0.005"/>
  </joint>

  <!-- ========================= MOTOR 3 ========================= -->
  <link name="motor_3">
    <inertial>
      <origin xyz="0 0 0" rpy="0 0 0"/>
      <mass value="0.072"/>
      <inertia ixx="8.928e-06" ixy="0" ixz="0" 
               iyy="8.928e-06" iyz="0" izz="7.056e-06"/>
    </inertial>
    <visual>
      <origin xyz="0 0 0" rpy="0 0 0"/>
      <geometry>
        <cylinder radius="0.014" length="0.032"/>
      </geometry>
      <material name="motor_material"/>
    </visual>
    <collision>
      <origin xyz="0 0 0" rpy="0 0 0"/>
      <geometry>
        <cylinder radius="0.014" length="0.032"/>
      </geometry>
    </collision>
  </link>

  <joint name="base_motor_3" type="fixed">
    <parent link="base_link"/>
    <child link="motor_3"/>
    <origin xyz="0.255691 0.1475 0.0695" rpy="0 0 0"/>
  </joint>

  <!-- ========================= ROTOR 4 ========================= -->
  <link name="rotor_4">
    <inertial>
      <origin xyz="0 0 0" rpy="0 0 0"/>
      <mass value="0.008"/>
      <inertia ixx="5.205e-05" ixy="0" ixz="0" 
               iyy="2.667e-07" iyz="0" izz="5.230e-05"/>
    </inertial>
    <visual>
      <origin xyz="0 0 0" rpy="0 0 0"/>
      <geometry>
        <mesh filename="file:///home/lahiru/newlocalrepo/rl-aerial-manipulator/hexacopter_description/custom_hexa/meshes/prop_ccw_CG.stl" 
              scale="0.001 0.001 0.001"/>
      </geometry>
      <material name="rotor_material"/>
    </visual>
    <collision>
      <origin xyz="0 0 0" rpy="0 0 0"/>
      <geometry>
        <cylinder radius="0.128" length="0.005"/>
      </geometry>
    </collision>
  </link>

  <joint name="rotor_4_joint" type="continuous">
    <parent link="base_link"/>
    <child link="rotor_4"/>
    <origin xyz="0 0.295 0.0915" rpy="0 0 0"/>
    <axis xyz="0 0 1"/>
    <limit effort="100000" velocity="4000"/>
    <dynamics damping="0.005"/>
  </joint>

  <!-- ========================= MOTOR 4 ========================= -->
  <link name="motor_4">
    <inertial>
      <origin xyz="0 0 0" rpy="0 0 0"/>
      <mass value="0.072"/>
      <inertia ixx="8.928e-06" ixy="0" ixz="0" 
               iyy="8.928e-06" iyz="0" izz="7.056e-06"/>
    </inertial>
    <visual>
      <origin xyz="0 0 0" rpy="0 0 0"/>
      <geometry>
        <cylinder radius="0.014" length="0.032"/>
      </geometry>
      <material name="motor_material"/>
    </visual>
    <collision>
      <origin xyz="0 0 0" rpy="0 0 0"/>
      <geometry>
        <cylinder radius="0.014" length="0.032"/>
      </geometry>
    </collision>
  </link>

  <joint name="base_motor_4" type="fixed">
    <parent link="base_link"/>
    <child link="motor_4"/>
    <origin xyz="0 0.295 0.0695" rpy="0 0 0"/>
  </joint>

  <!-- ========================= ROTOR 5 ========================= -->
  <link name="rotor_5">
    <inertial>
      <origin xyz="0 0 0" rpy="0 0 0"/>
      <mass value="0.008"/>
      <inertia ixx="5.205e-05" ixy="0" ixz="0" 
               iyy="2.667e-07" iyz="0" izz="5.230e-05"/>
    </inertial>
    <visual>
      <origin xyz="0 0 0" rpy="0 0 0"/>
      <geometry>
        <mesh filename="file:///home/lahiru/newlocalrepo/rl-aerial-manipulator/hexacopter_description/custom_hexa/meshes/prop_cw_CG.stl" 
              scale="0.001 0.001 0.001"/>
      </geometry>
      <material name="rotor_material"/>
    </visual>
    <collision>
      <origin xyz="0 0 0" rpy="0 0 0"/>
      <geometry>
        <cylinder radius="0.128" length="0.005"/>
      </geometry>
    </collision>
  </link>

  <joint name="rotor_5_joint" type="continuous">
    <parent link="base_link"/>
    <child link="rotor_5"/>
    <origin xyz="0 -0.295 0.0915" rpy="0 0 -2.09439510239"/>
    <axis xyz="0 0 1"/>
    <limit effort="100000" velocity="4000"/>
    <dynamics damping="0.005"/>
  </joint>

  <!-- ========================= MOTOR 5 ========================= -->
  <link name="motor_5">
    <inertial>
      <origin xyz="0 0 0" rpy="0 0 0"/>
      <mass value="0.072"/>
      <inertia ixx="8.928e-06" ixy="0" ixz="0" 
               iyy="8.928e-06" iyz="0" izz="7.056e-06"/>
    </inertial>
    <visual>
      <origin xyz="0 0 0" rpy="0 0 0"/>
      <geometry>
        <cylinder radius="0.014" length="0.032"/>
      </geometry>
      <material name="motor_material"/>
    </visual>
    <collision>
      <origin xyz="0 0 0" rpy="0 0 0"/>
      <geometry>
        <cylinder radius="0.014" length="0.032"/>
      </geometry>
    </collision>
  </link>

  <joint name="base_motor_5" type="fixed">
    <parent link="base_link"/>
    <child link="motor_5"/>
    <origin xyz="0 -0.295 0.0695" rpy="0 0 -2.09439510239"/>
  </joint>

  <!-- ========================= LANDING GEAR 1 ========================= -->
  <link name="landing_gear_1">
    <inertial>
      <origin xyz="0 0 -0.151575" rpy="0 0 0"/>
      <mass value="0.02825"/>
      <inertia ixx="2.17e-04" ixy="0" ixz="0" 
               iyy="2.17e-04" iyz="0" izz="7.73e-07"/>
    </inertial>
    <visual>
      <origin xyz="0 0 -0.151575" rpy="0 0 0"/>
      <geometry>
        <box size="0.01 0.01 0.30315"/>
      </geometry>
      <material name="landing_gear_material">
        <color rgba="1.0 1.0 1.0 1"/>
      </material>
    </visual>
    <collision>
      <origin xyz="0 0 -0.151575" rpy="0 0 0"/>
      <geometry>
        <box size="0.01 0.01 0.30315"/>
      </geometry>
    </collision>
  </link>

  <joint name="base_landing_gear_1" type="fixed">
    <parent link="base_link"/>
    <child link="landing_gear_1"/>
    <origin xyz="0 0.1874 0.0435" rpy="0 0.523598776 -1.57079632679"/>
  </joint>

  <!-- ========================= LANDING GEAR 2 ========================= -->
  <link name="landing_gear_2">
    <inertial>
      <origin xyz="0 0 -0.151575" rpy="0 0 0"/>
      <mass value="0.02825"/>
      <inertia ixx="2.17e-04" ixy="0" ixz="0" 
               iyy="2.17e-04" iyz="0" izz="7.73e-07"/>
    </inertial>
    <visual>
      <origin xyz="0 0 -0.151575" rpy="0 0 0"/>
      <geometry>
        <box size="0.01 0.01 0.30315"/>
      </geometry>
      <material name="landing_gear_material"/>
    </visual>
    <collision>
      <origin xyz="0 0 -0.151575" rpy="0 0 0"/>
      <geometry>
        <box size="0.01 0.01 0.30315"/>
      </geometry>
    </collision>
  </link>

  <joint name="base_landing_gear_2" type="fixed">
    <parent link="base_link"/>
    <child link="landing_gear_2"/>
    <origin xyz="0.162293160669 0.0937 0.0435" rpy="0 0.523598776 3.66519142919"/>
  </joint>

  <!-- ========================= LANDING GEAR 3 ========================= -->
  <link name="landing_gear_3">
    <inertial>
      <origin xyz="0 0 -0.151575" rpy="0 0 0"/>
      <mass value="0.02825"/>
      <inertia ixx="2.17e-04" ixy="0" ixz="0" 
               iyy="2.17e-04" iyz="0" izz="7.73e-07"/>
    </inertial>
    <visual>
      <origin xyz="0 0 -0.151575" rpy="0 0 0"/>
      <geometry>
        <box size="0.01 0.01 0.30315"/>
      </geometry>
      <material name="landing_gear_material"/>
    </visual>
    <collision>
      <origin xyz="0 0 -0.151575" rpy="0 0 0"/>
      <geometry>
        <box size="0.01 0.01 0.30315"/>
      </geometry>
    </collision>
  </link>

  <joint name="base_landing_gear_3" type="fixed">
    <parent link="base_link"/>
    <child link="landing_gear_3"/>
    <origin xyz="0.162293160669 -0.0937 0.0435" rpy="0 0.523598776 2.61799387799"/>
  </joint>

  <!-- ========================= LANDING GEAR 4 ========================= -->
  <link name="landing_gear_4">
    <inertial>
      <origin xyz="0 0 -0.151575" rpy="0 0 0"/>
      <mass value="0.02825"/>
      <inertia ixx="2.17e-04" ixy="0" ixz="0" 
               iyy="2.17e-04" iyz="0" izz="7.73e-07"/>
    </inertial>
    <visual>
      <origin xyz="0 0 -0.151575" rpy="0 0 0"/>
      <geometry>
        <box size="0.01 0.01 0.30315"/>
      </geometry>
      <material name="landing_gear_material"/>
    </visual>
    <collision>
      <origin xyz="0 0 -0.151575" rpy="0 0 0"/>
      <geometry>
        <box size="0.01 0.01 0.30315"/>
      </geometry>
    </collision>
  </link>

  <joint name="base_landing_gear_4" type="fixed">
    <parent link="base_link"/>
    <child link="landing_gear_4"/>
    <origin xyz="0 -0.1874 0.0435" rpy="0 0.523598776 1.57079632679"/>
  </joint>

  <!-- ========================= LANDING GEAR 5 ========================= -->
  <link name="landing_gear_5">
    <inertial>
      <origin xyz="0 0 -0.151575" rpy="0 0 0"/>
      <mass value="0.02825"/>
      <inertia ixx="2.17e-04" ixy="0" ixz="0" 
               iyy="2.17e-04" iyz="0" izz="7.73e-07"/>
    </inertial>
    <visual>
      <origin xyz="0 0 -0.151575" rpy="0 0 0"/>
      <geometry>
        <box size="0.01 0.01 0.30315"/>
      </geometry>
      <material name="landing_gear_material"/>
    </visual>
    <collision>
      <origin xyz="0 0 -0.151575" rpy="0 0 0"/>
      <geometry>
        <box size="0.01 0.01 0.30315"/>
      </geometry>
    </collision>
  </link>

  <joint name="base_landing_gear_5" type="fixed">
    <parent link="base_link"/>
    <child link="landing_gear_5"/>
    <origin xyz="-0.162293160669 -0.0937 0.0435" rpy="0 0.523598776 0.523598775598"/>
  </joint>

  <!-- ========================= LANDING GEAR 6 ========================= -->
  <link name="landing_gear_6">
    <inertial>
      <origin xyz="0 0 -0.151575" rpy="0 0 0"/>
      <mass value="0.02825"/>
      <inertia ixx="2.17e-04" ixy="0" ixz="0" 
               iyy="2.17e-04" iyz="0" izz="7.73e-07"/>
    </inertial>
    <visual>
      <origin xyz="0 0 -0.151575" rpy="0 0 0"/>
      <geometry>
        <box size="0.01 0.01 0.30315"/>
      </geometry>
      <material name="landing_gear_material"/>
    </visual>
    <collision>
      <origin xyz="0 0 -0.151575" rpy="0 0 0"/>
      <geometry>
        <box size="0.01 0.01 0.30315"/>
      </geometry>
    </collision>
  </link>

  <joint name="base_landing_gear_6" type="fixed">
    <parent link="base_link"/>
    <child link="landing_gear_6"/>
    <origin xyz="-0.162293160669 0.0937 0.0435" rpy="0 0.523598776 -0.523598775598"/>
  </joint>

  <!-- ========================= GAZEBO PLUGINS & SENSORS ========================= -->
  
  <!-- IMU Sensor -->
  <gazebo reference="base_link">
    <sensor name="imu_sensor" type="imu">
      <pose>0 0 0.02 0 0 0</pose>
      <always_on>1</always_on>
      <update_rate>250</update_rate>
      <imu>
        <angular_velocity>
          <x><noise type="gaussian"><mean>0</mean><stddev>0.0003394</stddev></noise></x>
          <y><noise type="gaussian"><mean>0</mean><stddev>0.0003394</stddev></noise></y>
          <z><noise type="gaussian"><mean>0</mean><stddev>0.0003394</stddev></noise></z>
        </angular_velocity>
        <linear_acceleration>
          <x><noise type="gaussian"><mean>0</mean><stddev>0.004</stddev></noise></x>
          <y><noise type="gaussian"><mean>0</mean><stddev>0.004</stddev></noise></y>
          <z><noise type="gaussian"><mean>0</mean><stddev>0.004</stddev></noise></z>
        </linear_acceleration>
      </imu>
    </sensor>
  </gazebo>

  <!-- Air Pressure Sensor -->
  <gazebo reference="base_link">
    <sensor name="air_pressure_sensor" type="air_pressure">
      <always_on>1</always_on>
      <update_rate>50</update_rate>
    </sensor>
  </gazebo>

  <!-- GPS/NavSat Sensor -->
  <gazebo reference="base_link">
    <sensor name="navsat_sensor" type="navsat">
      <pose>0 0 0.03 0 0 0</pose>
      <always_on>1</always_on>
      <update_rate>10</update_rate>
    </sensor>
  </gazebo>

  <!-- Magnetometer Sensor -->
  <gazebo reference="base_link">
    <sensor name="magnetometer_sensor" type="magnetometer">
      <pose>0 0 0.02 0 0 0</pose>
      <always_on>1</always_on>
      <update_rate>100</update_rate>
    </sensor>
  </gazebo>

  <!-- Motor Model Plugins -->
  <gazebo>
    <plugin filename="gz-sim-multicopter-motor-model-system" name="gz::sim::systems::MulticopterMotorModel">
      <robotNamespace>custom_hexa_0</robotNamespace>
      <jointName>rotor_0_joint</jointName>
      <linkName>rotor_0</linkName>
      <turningDirection>cw</turningDirection>
      <timeConstantUp>0.015</timeConstantUp>
      <timeConstantDown>0.015</timeConstantDown>
      <maxRotVelocity>820.0</maxRotVelocity>
      <motorConstant>2.11e-05</motorConstant>
      <momentConstant>0.0168</momentConstant>
      <commandSubTopic>command/motor_speed</commandSubTopic>
      <actuator_number>0</actuator_number>
      <rotorDragCoefficient>8.06428e-05</rotorDragCoefficient>
      <rollingMomentCoefficient>1e-06</rollingMomentCoefficient>
      <rotorVelocitySlowdownSim>10</rotorVelocitySlowdownSim>
      <motorType>velocity</motorType>
    </plugin>

    <plugin filename="gz-sim-multicopter-motor-model-system" name="gz::sim::systems::MulticopterMotorModel">
      <robotNamespace>custom_hexa_0</robotNamespace>
      <jointName>rotor_1_joint</jointName>
      <linkName>rotor_1</linkName>
      <turningDirection>ccw</turningDirection>
      <timeConstantUp>0.015</timeConstantUp>
      <timeConstantDown>0.015</timeConstantDown>
      <maxRotVelocity>820.0</maxRotVelocity>
      <motorConstant>2.11e-05</motorConstant>
      <momentConstant>0.0168</momentConstant>
      <commandSubTopic>command/motor_speed</commandSubTopic>
      <actuator_number>1</actuator_number>
      <rotorDragCoefficient>8.06428e-05</rotorDragCoefficient>
      <rollingMomentCoefficient>1e-06</rollingMomentCoefficient>
      <rotorVelocitySlowdownSim>10</rotorVelocitySlowdownSim>
      <motorType>velocity</motorType>
    </plugin>

    <plugin filename="gz-sim-multicopter-motor-model-system" name="gz::sim::systems::MulticopterMotorModel">
      <robotNamespace>custom_hexa_0</robotNamespace>
      <jointName>rotor_2_joint</jointName>
      <linkName>rotor_2</linkName>
      <turningDirection>ccw</turningDirection>
      <timeConstantUp>0.015</timeConstantUp>
      <timeConstantDown>0.015</timeConstantDown>
      <maxRotVelocity>820.0</maxRotVelocity>
      <motorConstant>2.11e-05</motorConstant>
      <momentConstant>0.0168</momentConstant>
      <commandSubTopic>command/motor_speed</commandSubTopic>
      <actuator_number>2</actuator_number>
      <rotorDragCoefficient>8.06428e-05</rotorDragCoefficient>
      <rollingMomentCoefficient>1e-06</rollingMomentCoefficient>
      <rotorVelocitySlowdownSim>10</rotorVelocitySlowdownSim>
      <motorType>velocity</motorType>
    </plugin>

    <plugin filename="gz-sim-multicopter-motor-model-system" name="gz::sim::systems::MulticopterMotorModel">
      <robotNamespace>custom_hexa_0</robotNamespace>
      <jointName>rotor_3_joint</jointName>
      <linkName>rotor_3</linkName>
      <turningDirection>cw</turningDirection>
      <timeConstantUp>0.015</timeConstantUp>
      <timeConstantDown>0.015</timeConstantDown>
      <maxRotVelocity>820.0</maxRotVelocity>
      <motorConstant>2.11e-05</motorConstant>
      <momentConstant>0.0168</momentConstant>
      <commandSubTopic>command/motor_speed</commandSubTopic>
      <actuator_number>3</actuator_number>
      <rotorDragCoefficient>8.06428e-05</rotorDragCoefficient>
      <rollingMomentCoefficient>1e-06</rollingMomentCoefficient>
      <rotorVelocitySlowdownSim>10</rotorVelocitySlowdownSim>
      <motorType>velocity</motorType>
    </plugin>

    <plugin filename="gz-sim-multicopter-motor-model-system" name="gz::sim::systems::MulticopterMotorModel">
      <robotNamespace>custom_hexa_0</robotNamespace>
      <jointName>rotor_4_joint</jointName>
      <linkName>rotor_4</linkName>
      <turningDirection>ccw</turningDirection>
      <timeConstantUp>0.015</timeConstantUp>
      <timeConstantDown>0.015</timeConstantDown>
      <maxRotVelocity>820.0</maxRotVelocity>
      <motorConstant>2.11e-05</motorConstant>
      <momentConstant>0.0168</momentConstant>
      <commandSubTopic>command/motor_speed</commandSubTopic>
      <actuator_number>4</actuator_number>
      <rotorDragCoefficient>8.06428e-05</rotorDragCoefficient>
      <rollingMomentCoefficient>1e-06</rollingMomentCoefficient>
      <rotorVelocitySlowdownSim>10</rotorVelocitySlowdownSim>
      <motorType>velocity</motorType>
    </plugin>

    <plugin filename="gz-sim-multicopter-motor-model-system" name="gz::sim::systems::MulticopterMotorModel">
      <robotNamespace>custom_hexa_0</robotNamespace>
      <jointName>rotor_5_joint</jointName>
      <linkName>rotor_5</linkName>
      <turningDirection>cw</turningDirection>
      <timeConstantUp>0.015</timeConstantUp>
      <timeConstantDown>0.015</timeConstantDown>
      <maxRotVelocity>820.0</maxRotVelocity>
      <motorConstant>2.11e-05</motorConstant>
      <momentConstant>0.0168</momentConstant>
      <commandSubTopic>command/motor_speed</commandSubTopic>
      <actuator_number>5</actuator_number>
      <rotorDragCoefficient>8.06428e-05</rotorDragCoefficient>
      <rollingMomentCoefficient>1e-06</rollingMomentCoefficient>
      <rotorVelocitySlowdownSim>10</rotorVelocitySlowdownSim>
      <motorType>velocity</motorType>
    </plugin>
  </gazebo>

</robot>
